2025-05-05 04:36:17,404 INFO    StreamThr :18736 [internal.py:wandb_internal():85] W&B internal server running at pid: 18736, started at: 2025-05-05 04:36:17.404392
2025-05-05 04:36:17,406 DEBUG   HandlerThread:18736 [handler.py:handle_request():158] handle_request: status
2025-05-05 04:36:17,408 INFO    WriterThread:18736 [datastore.py:open_for_write():87] open: /workspace/anole_training/wandb/run-20250505_043617-9x4yh7cb/run-9x4yh7cb.wandb
2025-05-05 04:36:17,409 DEBUG   SenderThread:18736 [sender.py:send():379] send: header
2025-05-05 04:36:17,412 DEBUG   SenderThread:18736 [sender.py:send():379] send: run
2025-05-05 04:36:17,672 ERROR   SenderThread:18736 [internal_api.py:execute():349] 404 response executing GraphQL.
2025-05-05 04:36:17,672 ERROR   SenderThread:18736 [internal_api.py:execute():350] {"errors":[{"message":"entity anole-ai not found during upsertBucket","path":["upsertBucket"]}],"data":{"upsertBucket":null}}
2025-05-05 04:36:17,672 ERROR   SenderThread:18736 [sender.py:send_run():1009] It appears that you do not have permission to access the requested resource. Please reach out to the project owner to grant you access. If you have the correct permissions, verify that there are no issues with your networking setup.(Error 404: Not Found)
Traceback (most recent call last):
  File "/venv/main/lib/python3.10/site-packages/wandb/sdk/lib/retry.py", line 131, in __call__
    result = self._call_fn(*args, **kwargs)
  File "/venv/main/lib/python3.10/site-packages/wandb/sdk/internal/internal_api.py", line 345, in execute
    return self.client.execute(*args, **kwargs)  # type: ignore
  File "/venv/main/lib/python3.10/site-packages/wandb/vendor/gql-0.2.0/wandb_gql/client.py", line 52, in execute
    result = self._get_result(document, *args, **kwargs)
  File "/venv/main/lib/python3.10/site-packages/wandb/vendor/gql-0.2.0/wandb_gql/client.py", line 60, in _get_result
    return self.transport.execute(document, *args, **kwargs)
  File "/venv/main/lib/python3.10/site-packages/wandb/sdk/lib/gql_request.py", line 59, in execute
    request.raise_for_status()
  File "/venv/main/lib/python3.10/site-packages/requests/models.py", line 1024, in raise_for_status
    raise HTTPError(http_error_msg, response=self)
requests.exceptions.HTTPError: 404 Client Error: Not Found for url: https://api.wandb.ai/graphql

During handling of the above exception, another exception occurred:

Traceback (most recent call last):
  File "/venv/main/lib/python3.10/site-packages/wandb/sdk/internal/sender.py", line 1007, in send_run
    server_run = self._init_run(run, config_value_dict)
  File "/venv/main/lib/python3.10/site-packages/wandb/sdk/internal/sender.py", line 1079, in _init_run
    server_run, inserted, server_messages = self._api.upsert_run(
  File "/venv/main/lib/python3.10/site-packages/wandb/apis/normalize.py", line 73, in wrapper
    raise err
  File "/venv/main/lib/python3.10/site-packages/wandb/apis/normalize.py", line 41, in wrapper
    return func(*args, **kwargs)
  File "/venv/main/lib/python3.10/site-packages/wandb/sdk/internal/internal_api.py", line 2224, in upsert_run
    response = self.gql(
  File "/venv/main/lib/python3.10/site-packages/wandb/sdk/internal/internal_api.py", line 317, in gql
    ret = self._retry_gql(
  File "/venv/main/lib/python3.10/site-packages/wandb/sdk/lib/retry.py", line 147, in __call__
    retry_timedelta_triggered = check_retry_fn(e)
  File "/venv/main/lib/python3.10/site-packages/wandb/util.py", line 968, in check_retry_fn
    return fallback_retry_fn(e)
  File "/venv/main/lib/python3.10/site-packages/wandb/util.py", line 910, in no_retry_auth
    raise CommError(
wandb.errors.CommError: It appears that you do not have permission to access the requested resource. Please reach out to the project owner to grant you access. If you have the correct permissions, verify that there are no issues with your networking setup.(Error 404: Not Found)
2025-05-05 04:36:17,822 DEBUG   HandlerThread:18736 [handler.py:handle_request():158] handle_request: shutdown
2025-05-05 04:36:17,822 INFO    HandlerThread:18736 [handler.py:finish():882] shutting down handler
2025-05-05 04:36:18,412 INFO    WriterThread:18736 [datastore.py:close():296] close: /workspace/anole_training/wandb/run-20250505_043617-9x4yh7cb/run-9x4yh7cb.wandb
2025-05-05 04:36:18,674 INFO    SenderThread:18736 [sender.py:finish():1608] shutting down sender
